<robot name="7DOF_ROBOT">
    <!-- World -->
    <link name="world"/>

    <!-- World link Base -->
    <joint name="fixed" type="fixed">
        <origin xyz="0.0 0.0 1" rpy="0.0 1.57 0.0"/>
        <parent link="world"/>
        <child link="Base"/>
    </joint>

    <!-- Base  -->
    <link name="Base">
        <visual>
            <geometry>
                <mesh filename="../meshes/Base.STL" />
            </geometry>
        </visual>
        <collision>
            <geometry>
                <mesh filename="../meshes/Base.STL"/>
            </geometry>
        </collision>
    </link>

    <!-- q1 -->
    <joint name="q1" type="revolute">
        <origin xyz="0.0 0.0 0.0" rpy="0.0 0.0 0.0"/>
        <parent link="Base"/>
        <child link="Joint1"/>
        <axis xyz="0 0 1"/>
        <limit lower="-3.14" upper="3.14" effort="1000" velocity="0.0"/>
    </joint>

    <!-- Joint1 -->
    <link name="Joint1">
        <visual>
            <geometry>
                <mesh filename="../meshes/Joint1.STL" />
            </geometry>
        </visual>
        <collision>
            <geometry>
                <mesh filename="../meshes/Joint1.STL"/>
            </geometry>
        </collision>
    </link>

    <!-- q2 -->
    <joint name="q2" type="revolute">
        <origin xyz="0.0 0.045 0.045" rpy="-1.57 0.0 0.0"/>
        <parent link="Joint1"/>
        <child link="Link1"/>
        <axis xyz="0 0 1"/>
        <limit lower="-3.14" upper="3.14" effort="1000" velocity="0.0"/>
    </joint>

    <!-- Link1  -->
    <link name="Link1">
        <visual>
            <geometry>
                <mesh filename="../meshes/Link1.STL" />
            </geometry>
        </visual>
        <collision>
            <geometry>
                <mesh filename="../meshes/Link1.STL"/>
            </geometry>
        </collision>
    </link>

    <!-- q3 -->
    <joint name="q3" type="revolute">
        <origin xyz="0.345 0.0 0.045" rpy="0.0 -1.57 3.14"/>
        <parent link="Link1"/>
        <child link="Joint2"/>
        <axis xyz="0 0 1"/>
        <limit lower="-3.14" upper="3.14" effort="1000" velocity="0.0"/>
    </joint>

    <!-- Joint2 -->
    <link name="Joint2">
        <visual>
            <geometry>
                <mesh filename="../meshes/Joint1.STL" />
            </geometry>
        </visual>
        <collision>
            <geometry>
                <mesh filename="../meshes/Joint1.STL"/>
            </geometry>
        </collision>
    </link>

    <!-- q4 -->
    <joint name="q4" type="revolute">
        <origin xyz="0.0 0.045 0.045" rpy="-1.57 -1.57 0.0"/>
        <parent link="Joint2"/>
        <child link="Link2"/>
        <axis xyz="0 0 1"/>
        <limit lower="-3.14" upper="3.14" effort="1000" velocity="0.0"/>
    </joint>

    <!-- Link2  -->
    <link name="Link2">
        <visual>
            <geometry>
                <mesh filename="../meshes/Link1.STL" />
            </geometry>
        </visual>
        <collision>
            <geometry>
                <mesh filename="../meshes/Link1.STL"/>
            </geometry>
        </collision>
    </link>

    <!-- q5 -->
    <joint name="q5" type="revolute">
        <origin xyz="0.345 0.0 0.045" rpy="0.0 1.57 0.0"/>
        <parent link="Link2"/>
        <child link="Joint3"/>
        <axis xyz="0 0 1"/>
        <limit lower="-3.14" upper="3.14" effort="1000" velocity="0.0"/>
    </joint>

    <!-- Joint3 -->
    <link name="Joint3">
        <visual>
            <geometry>
                <mesh filename="../meshes/Joint1.STL" />
            </geometry>
        </visual>
        <collision>
            <geometry>
                <mesh filename="../meshes/Joint1.STL"/>
            </geometry>
        </collision>
    </link>

    <!-- q6 -->
    <joint name="q6" type="revolute">
        <origin xyz="0.0 0.045 0.045" rpy="-1.57 1.57 0.0"/>
        <parent link="Joint3"/>
        <child link="Joint4"/>
        <axis xyz="0 0 1"/>
        <limit lower="-3.14" upper="3.14" effort="1000" velocity="0.0"/>
    </joint>

    <!-- Joint4 -->
    <link name="Joint4">
        <visual>
            <geometry>
                <mesh filename="../meshes/Joint1.STL" />
            </geometry>
        </visual>
        <collision>
            <geometry>
                <mesh filename="../meshes/Joint1.STL"/>
            </geometry>
        </collision>
    </link>

    <!-- q7 -->
    <joint name="q7" type="revolute">
        <origin xyz="0.0 0.045 0.045" rpy="-1.57 1.57 0.0"/>
        <parent link="Joint4"/>
        <child link="Gripper"/>
        <axis xyz="0 0 1"/>
        <limit lower="-3.14" upper="3.14" effort="1000" velocity="0.0"/>
    </joint>

    <!-- Gripper -->
    <link name="Gripper">
        <visual>
            <geometry>
                <mesh filename="../meshes/Gripper.STL" />
            </geometry>
        </visual>
        <collision>
            <geometry>
                <mesh filename="../meshes/Gripper.STL"/>
            </geometry>
        </collision>
    </link>

</robot>
